<?xml version="1.0" ?>
<!-- =================================================================================== -->
<!-- |    This document was autogenerated by xacro from ilk_robot_xacro.xml            | -->
<!-- |    EDITING THIS FILE BY HAND IS NOT RECOMMENDED                                 | -->
<!-- =================================================================================== -->
<robot name="robot_kolu">
  <link name="base_link">
    <visual>
      <geometry>
        <cylinder length="0.05" radius="0.15"/>
      </geometry>
      <origin rpy="0.0 0.0 0.0" xyz="0.0 0.0 0.0"/>
      <material name="yesil">
        <color rgba="0 1 0 1">

                </color>
      </material>
    </visual>
    <collision>
      <geometry>
        <cylinder length="0.05" radius="0.15"/>
      </geometry>
      <origin rpy="0.0 0.0 0.0" xyz="0.0 0.0 0.0"/>
    </collision>
    <inertial>
      <mass value="10.0"/>
      <inertia ixx="0.5" ixy="0.0" ixz="0.0" iyy="0.5" iyz="0.0" izz="0.5"/>
    </inertial>
  </link>
  <joint name="govde_eklemi" type="revolute">
    <origin rpy="0.0 0.0 0.0" xyz="0.0 0.0 0.0"/>
    <axis xyz="0 0 1 "/>
    <parent link="base_link"/>
    <child link="govde_uzvu"/>
    <calibration rising="0.0"/>
    <dynamics damping="0.0" friction="0.0"/>
    <limit effort="30" lower="-1.57" upper="1.57" velocity="1.0"/>
    <safety_controller k_position="100" k_velocity="1.5" soft_lower_limit="-2.857" soft_upper_limit="2.857"/>
  </joint>
  <link name="govde_uzvu">
    <visual>
      <geometry>
        <box size="0.2 0.2 0.7"/>
      </geometry>
      <origin rpy="0.0 0.0 0.0" xyz="0.0 0.0 0.35"/>
      <material name="kirmizi">
        <color rgba="1 0 0 1">
                </color>
      </material>
    </visual>
    <collision>
      <geometry>
        <box size="0.2 0.2 0.7"/>
      </geometry>
      <origin rpy="0.0 0.0 0.0" xyz="0.0 0.0 0.0"/>
    </collision>
    <inertial>
      <mass value="1.0"/>
      <inertia ixx="0.5" ixy="0.0" ixz="0.0" iyy="0.5" iyz="0.0" izz="0.5"/>
    </inertial>
  </link>
  <joint name="kol_eklemi_sol" type="revolute">
    <origin rpy="0.0 0.0 0.0" xyz="0.05 0.0 0.5"/>
    <axis xyz="1 0 0 "/>
    <parent link="govde_uzvu"/>
    <child link="kol_sol"/>
    <calibration rising="0.0"/>
    <dynamics damping="0.0" friction="0.0"/>
    <limit effort="30" lower="0.0" upper="3.14" velocity="1.0"/>
    <safety_controller k_position="100" k_velocity="1.5" soft_lower_limit="-2.857" soft_upper_limit="2.857"/>
  </joint>
  <link name="kol_sol">
    <visual>
      <geometry>
        <box size="0.04 0.04 0.3"/>
      </geometry>
      <origin rpy="0.0 0.0 0.0" xyz="0.07 0.0 0.15"/>
      <material name="sari">
        <color rgba="0 1 1 1">
                </color>
      </material>
    </visual>
    <collision>
      <geometry>
        <box size="0.04 0.04 0.3"/>
      </geometry>
      <origin rpy="0.0 0.0 0.0" xyz="0.025 0.0 0.15"/>
    </collision>
    <inertial>
      <mass value="1"/>
      <inertia ixx="0.5" ixy="0.0" ixz="0.0" iyy="0.5" iyz="0.0" izz="0.5"/>
    </inertial>
  </link>
  <joint name="kol_eklemi_sag" type="revolute">
    <origin rpy="0.0 0.0 0.0" xyz="-0.05 0.0 0.5"/>
    <axis xyz="1 0 0 "/>
    <parent link="govde_uzvu"/>
    <child link="kol_sag"/>
    <calibration rising="0.0"/>
    <dynamics damping="0.0" friction="0.0"/>
    <limit effort="30" lower="0.0" upper="3.14" velocity="1.0"/>
    <safety_controller k_position="100" k_velocity="1.5" soft_lower_limit="-2.857" soft_upper_limit="2.857"/>
  </joint>
  <link name="kol_sag">
    <visual>
      <geometry>
        <box size="0.04 0.04 0.3"/>
      </geometry>
      <origin rpy="0.0 0.0 0.0" xyz="-0.07 0.0 0.15"/>
      <material name="sari">
        <color rgba="1 0 0 1">
                </color>
      </material>
    </visual>
    <collision>
      <geometry>
        <box size="0.04 0.04 0.3"/>
      </geometry>
      <origin rpy="0.0 0.0 0.0" xyz="0.025 0.0 0.15"/>
    </collision>
    <inertial>
      <mass value="1"/>
      <inertia ixx="0.5" ixy="0.0" ixz="0.0" iyy="0.5" iyz="0.0" izz="0.5"/>
    </inertial>
  </link>
  <joint name="kafa_eklemi" type="revolute">
    <origin rpy="0.0 0.0 0.0" xyz="0.0 0.0 0.0"/>
    <axis xyz="0 0 1 "/>
    <parent link="govde_uzvu"/>
    <child link="kafa"/>
    <calibration rising="0.0"/>
    <dynamics damping="0.0" friction="0.0"/>
    <limit effort="30" lower="-1.57" upper="1.57" velocity="1.0"/>
    <safety_controller k_position="100" k_velocity="1.5" soft_lower_limit="-2.857" soft_upper_limit="2.857"/>
  </joint>
  <link name="kafa">
    <visual>
      <geometry>
        <sphere radius="0.1"/>
      </geometry>
      <origin rpy="0.0 0.0 0.0" xyz="0.0 0.0 0.8"/>
      <material name="karisik">
        <color rgba="1 0 1 1">
                </color>
      </material>
    </visual>
    <collision>
      <geometry>
        <sphere radius="0.1"/>
      </geometry>
      <origin rpy="0.0 0.0 0.0" xyz="0.025 0.0 0.15"/>
    </collision>
    <inertial>
      <mass value="1"/>
      <inertia ixx="0.5" ixy="0.0" ixz="0.0" iyy="0.5" iyz="0.0" izz="0.5"/>
    </inertial>
  </link>
  <link name="camera">
    <collision>
      <origin rpy="0 0 0" xyz="0 0 0"/>
      <geometry>
        <box size="1.5 1.5 0.5"/>
      </geometry>
    </collision>
    <visual>
      <origin rpy="0 0 0" xyz="0 0 0"/>
      <geometry>
        <box size="0.08 0.02 0.08"/>
      </geometry>
    </visual>
    <inertial>
      <mass value="1e-5"/>
      <origin rpy="0 0 0" xyz="0 0 0"/>
      <inertia ixx="0.2" ixy="0" ixz="0" iyy="0.2" iyz="0" izz="0.2"/>
    </inertial>
  </link>
  <joint name="sensor_joint" type="fixed">
    <parent link="kafa"/>
    <child link="camera"/>
    <origin rpy="0 0 0" xyz="0 -0.09 0.8"/>
  </joint>
  <gazebo reference="base_link">
    <material>Gazebo/Orange</material>
  </gazebo>
  <gazebo reference="govde_uzvu">
    <material>Gazebo/Green</material>
  </gazebo>
  <gazebo reference="kol_sol">
    <material>Gazebo/Black</material>
  </gazebo>
  <gazebo reference="kol_sag">
    <material>Gazebo/Black</material>
  </gazebo>
  <gazebo reference="kafa">
    <material>Gazebo/Red</material>
  </gazebo>
  <gazebo reference="camera">
    <material>Gazebo/Red</material>
  </gazebo>
  <gazebo reference="camera">
    <sensor name="camera" type="camera">
      <update_rate>30.0</update_rate>
      <camera name="head">
        <horizontal_fov>1.3962634</horizontal_fov>
        <image>
          <width>800</width>
          <height>600</height>
          <format>R8G8B8</format>
        </image>
        <clip>
          <near>0.02</near>
          <far>300</far>
        </clip>
        <noise>
          <type>gaussian</type>
          <mean>0.0</mean>
          <stddev>0.007</stddev>
        </noise>
      </camera>
      <plugin filename="libgazebo_ros_camera.so" name="camera_controller">
        <alwaysOn>true</alwaysOn>
        <updateRate>0.0</updateRate>
        <cameraName>camera</cameraName>
        <imageTopicName>image_raw</imageTopicName>
        <cameraInfoTopicName>camera_info</cameraInfoTopicName>
        <frameName>camera</frameName>
        <hackBaseline>0.07</hackBaseline>
        <distortionK1>0.0</distortionK1>
        <distortionK2>0.0</distortionK2>
        <distortionK3>0.0</distortionK3>
        <distortionT1>0.0</distortionT1>
        <distortionT2>0.0</distortionT2>
      </plugin>
    </sensor>
  </gazebo>
</robot>

